Error type: RuntimeError
Error message: Engine core initialization failed. See root cause above. Failed core proc(s): {}

Traceback (most recent call last):
  File "/home/tdeshane/vllm/patches/test_gptoss_fail.py", line 13, in <module>
    llm = LLM("openai/gpt-oss-20b", max_model_len=512, enforce_eager=True)
          ^^^^^^^^^^^^^^^^^^^^^^^^^^^^^^^^^^^^^^^^^^^^^^^^^^^^^^^^^^^^^^^^
  File "/home/tdeshane/miniconda3/envs/vllm_gptoss/lib/python3.12/site-packages/vllm/entrypoints/llm.py", line 277, in __init__
    self.llm_engine = LLMEngine.from_engine_args(
                      ^^^^^^^^^^^^^^^^^^^^^^^^^^^
  File "/home/tdeshane/miniconda3/envs/vllm_gptoss/lib/python3.12/site-packages/vllm/engine/llm_engine.py", line 494, in from_engine_args
    return engine_cls.from_vllm_config(
           ^^^^^^^^^^^^^^^^^^^^^^^^^^^^
  File "/home/tdeshane/miniconda3/envs/vllm_gptoss/lib/python3.12/site-packages/vllm/v1/engine/llm_engine.py", line 127, in from_vllm_config
    return cls(vllm_config=vllm_config,
           ^^^^^^^^^^^^^^^^^^^^^^^^^^^^
  File "/home/tdeshane/miniconda3/envs/vllm_gptoss/lib/python3.12/site-packages/vllm/v1/engine/llm_engine.py", line 104, in __init__
    self.engine_core = EngineCoreClient.make_client(
                       ^^^^^^^^^^^^^^^^^^^^^^^^^^^^^
  File "/home/tdeshane/miniconda3/envs/vllm_gptoss/lib/python3.12/site-packages/vllm/v1/engine/core_client.py", line 79, in make_client
    return SyncMPClient(vllm_config, executor_class, log_stats)
           ^^^^^^^^^^^^^^^^^^^^^^^^^^^^^^^^^^^^^^^^^^^^^^^^^^^^
  File "/home/tdeshane/miniconda3/envs/vllm_gptoss/lib/python3.12/site-packages/vllm/v1/engine/core_client.py", line 566, in __init__
    super().__init__(
  File "/home/tdeshane/miniconda3/envs/vllm_gptoss/lib/python3.12/site-packages/vllm/v1/engine/core_client.py", line 421, in __init__
    with launch_core_engines(vllm_config, executor_class,
         ^^^^^^^^^^^^^^^^^^^^^^^^^^^^^^^^^^^^^^^^^^^^^^^^
  File "/home/tdeshane/miniconda3/envs/vllm_gptoss/lib/python3.12/contextlib.py", line 144, in __exit__
    next(self.gen)
  File "/home/tdeshane/miniconda3/envs/vllm_gptoss/lib/python3.12/site-packages/vllm/v1/engine/utils.py", line 697, in launch_core_engines
    wait_for_engine_startup(
  File "/home/tdeshane/miniconda3/envs/vllm_gptoss/lib/python3.12/site-packages/vllm/v1/engine/utils.py", line 750, in wait_for_engine_startup
    raise RuntimeError("Engine core initialization failed. "
RuntimeError: Engine core initialization failed. See root cause above. Failed core proc(s): {}
